<?xml version="1.0" ?>
<robot name="rur_detailed" xmlns:xacro="http://www.ros.org/wiki/xacro">

<xacro:include filename="$(find rur_detailed_description)/urdf/materials.xacro" />
<!--<xacro:include filename="$(find rur_detailed_description)/urdf/rur_detailed.trans" />-->

<xacro:include filename="$(find rur_detailed_description)/gazebo/rur_detailed_materials.gazebo" />
<xacro:include filename="$(find rur_detailed_description)/gazebo/rur_detailed_physics.gazebo" />
<xacro:include filename="$(find rur_detailed_description)/gazebo/rur_detailed_plugins.gazebo" />

<link name="base_link">
  <inertial>
    <origin rpy="0 0 0" xyz="0.008717050480319273 0.0013081620436010979 0.15115173825671988"/>
    <mass value="15.428530536945836"/>
    <inertia ixx="0.257115" ixy="0.001043" ixz="-0.003282" iyy="0.342385" iyz="-0.001055" izz="0.481029"/>
  </inertial>
  <visual>
    <origin rpy="0 0 0" xyz="0 0 0"/>
    <geometry>
      <mesh filename="package://rur_detailed_description/meshes/base_link.stl" scale="0.001 0.001 0.001"/>
    </geometry>
    <material name="white"/>
  </visual>
  <collision>
    <origin rpy="0 0 0" xyz="0 0 0"/>
    <geometry>
      <mesh filename="package://rur_detailed_description/meshes/base_link.stl" scale="0.001 0.001 0.001"/>
    </geometry>
  </collision>
</link>

<link name="right_wheel">
  <inertial>
    <origin rpy="0 0 0" xyz="-1.828063402709465e-05 0.05312247246161367 0.0002521115303902449"/>
    <mass value="9.856921104469992"/>
    <inertia ixx="0.020599" ixy="-7e-06" ixz="2e-06" iyy="0.03491" iyz="-2.8e-05" izz="0.020606"/>
  </inertial>
  <visual>
    <origin rpy="0 0 0" xyz="-0.0 0.227 -0.099839"/>
    <geometry>
      <mesh filename="package://rur_detailed_description/meshes/right_wheel.stl" scale="0.001 0.001 0.001"/>
    </geometry>
    <material name="blue"/>
  </visual>
  <collision>
    <origin rpy="0 0 0" xyz="-0.0 0.227 -0.099839"/>
    <geometry>
      <mesh filename="package://rur_detailed_description/meshes/right_wheel.stl" scale="0.001 0.001 0.001"/>
    </geometry>
  </collision>
</link>

<link name="left_wheel">
  <inertial>
    <origin rpy="0 0 0" xyz="-1.8254554994090065e-05 -0.0531169103077688 0.0002522130405125389"/>
    <mass value="9.871217353742987"/>
    <inertia ixx="0.020624" ixy="7e-06" ixz="2e-06" iyy="0.034948" iyz="2.8e-05" izz="0.020631"/>
  </inertial>
  <visual>
    <origin rpy="0 0 0" xyz="0.0 -0.227 -0.099839"/>
    <geometry>
      <mesh filename="package://rur_detailed_description/meshes/left_wheel.stl" scale="0.001 0.001 0.001"/>
    </geometry>
    <material name="blue"/>
  </visual>
  <collision>
    <origin rpy="0 0 0" xyz="0.0 -0.227 -0.099839"/>
    <geometry>
      <mesh filename="package://rur_detailed_description/meshes/left_wheel.stl" scale="0.001 0.001 0.001"/>
    </geometry>
  </collision>
</link>

<link name="right_tyre">
  <inertial>
    <origin rpy="0 0 0" xyz="-5.919068486634321e-08 0.011578960710706687 0.00016105311301901903"/>
    <mass value="4.766678644162142"/>
    <inertia ixx="0.012277" ixy="-0.0" ixz="0.0" iyy="0.022304" iyz="-0.0" izz="0.012277"/>
  </inertial>
  <visual>
    <origin rpy="0 0 0" xyz="-0.0 0.2 -0.1"/>
    <geometry>
      <mesh filename="package://rur_detailed_description/meshes/right_tyre.stl" scale="0.001 0.001 0.001"/>
    </geometry>
    <material name="white"/>
  </visual>
  <collision>
    <origin rpy="0 0 0" xyz="-0.0 0.2 -0.1"/>
    <geometry>
      <mesh filename="package://rur_detailed_description/meshes/right_tyre.stl" scale="0.001 0.001 0.001"/>
    </geometry>
  </collision>
</link>

<link name="left_tyre">
  <inertial>
    <origin rpy="0 0 0" xyz="9.30327782468428e-09 -0.011578963887744514 0.000161051324790773"/>
    <mass value="4.766678875971219"/>
    <inertia ixx="0.012277" ixy="0.0" ixz="-0.0" iyy="0.022304" iyz="0.0" izz="0.012277"/>
  </inertial>
  <visual>
    <origin rpy="0 0 0" xyz="0.0 -0.2 -0.1"/>
    <geometry>
      <mesh filename="package://rur_detailed_description/meshes/left_tyre.stl" scale="0.001 0.001 0.001"/>
    </geometry>
    <material name="white"/>
  </visual>
  <collision>
    <origin rpy="0 0 0" xyz="0.0 -0.2 -0.1"/>
    <geometry>
      <mesh filename="package://rur_detailed_description/meshes/left_tyre.stl" scale="0.001 0.001 0.001"/>
    </geometry>
  </collision>
</link>

<link name="front_caster">
  <inertial>
    <origin rpy="0 0 0" xyz="-0.025000797505036393 -2.9865544783409456e-16 -0.030208086053412367"/>
    <mass value="0.4573656248802168"/>
    <inertia ixx="0.000244" ixy="-0.0" ixz="0.0" iyy="0.000244" iyz="0.0" izz="0.000192"/>
  </inertial>
  <visual>
    <origin rpy="0 0 0" xyz="-0.172 -0.0 -0.07"/>
    <geometry>
      <mesh filename="package://rur_detailed_description/meshes/front_caster.stl" scale="0.001 0.001 0.001"/>
    </geometry>
    <material name="blue"/>
  </visual>
  <collision>
    <origin rpy="0 0 0" xyz="-0.172 -0.0 -0.07"/>
    <geometry>
      <mesh filename="package://rur_detailed_description/meshes/front_caster.stl" scale="0.001 0.001 0.001"/>
    </geometry>
  </collision>
</link>

<link name="back_caster">
  <inertial>
    <origin rpy="0 0 0" xyz="0.024999202494963513 -3.2214520215812444e-16 -0.030208086053412374"/>
    <mass value="0.4573656248802169"/>
    <inertia ixx="0.000244" ixy="-0.0" ixz="0.0" iyy="0.000244" iyz="0.0" izz="0.000192"/>
  </inertial>
  <visual>
    <origin rpy="0 0 0" xyz="0.172 0.0 -0.07"/>
    <geometry>
      <mesh filename="package://rur_detailed_description/meshes/back_caster.stl" scale="0.001 0.001 0.001"/>
    </geometry>
    <material name="blue"/>
  </visual>
  <collision>
    <origin rpy="0 0 0" xyz="0.172 0.0 -0.07"/>
    <geometry>
      <mesh filename="package://rur_detailed_description/meshes/back_caster.stl" scale="0.001 0.001 0.001"/>
    </geometry>
  </collision>
</link>

<link name="lid">
  <inertial>
    <origin rpy="0 0 0" xyz="-0.20973058370001274 -0.0002000297507654507 0.021779111268977636"/>
    <mass value="18.187373287828525"/>
    <inertia ixx="0.290093" ixy="0.0" ixz="-0.003295" iyy="0.300261" iyz="0.0" izz="0.584949"/>
  </inertial>
  <visual>
    <origin rpy="0 0 0" xyz="-0.225 -0.0002 -0.25"/>
    <geometry>
      <mesh filename="package://rur_detailed_description/meshes/lid.stl" scale="0.001 0.001 0.001"/>
    </geometry>
    <material name="white"/>
  </visual>
  <collision>
    <origin rpy="0 0 0" xyz="-0.225 -0.0002 -0.25"/>
    <geometry>
      <mesh filename="package://rur_detailed_description/meshes/lid.stl" scale="0.001 0.001 0.001"/>
    </geometry>
  </collision>
</link>

<link name="lidar">
  <inertial>
    <origin rpy="0 0 0" xyz="-2.3483549826952554e-09 -3.4770506128023716e-07 0.009561590682608923"/>
    <mass value="0.0886181648250366"/>
    <inertia ixx="3.3e-05" ixy="0.0" ixz="0.0" iyy="3.3e-05" iyz="0.0" izz="6e-05"/>
  </inertial>
  <visual>
    <origin rpy="0 0 0" xyz="-0.1575 0.0 -0.3"/>
    <geometry>
      <mesh filename="package://rur_detailed_description/meshes/lidar.stl" scale="0.001 0.001 0.001"/>
    </geometry>
    <material name="black"/>
  </visual>
  <collision>
    <origin rpy="0 0 0" xyz="-0.1575 0.0 -0.3"/>
    <geometry>
      <mesh filename="package://rur_detailed_description/meshes/lidar.stl" scale="0.001 0.001 0.001"/>
    </geometry>
  </collision>
</link>

<link name="electronics_lid">
  <inertial>
    <origin rpy="0 0 0" xyz="-0.0511574994774171 -0.011997734212864706 -0.0015000000000000568"/>
    <mass value="0.633989646973267"/>
    <inertia ixx="0.003384" ixy="-9e-06" ixz="-0.0" iyy="0.000771" iyz="0.0" izz="0.004153"/>
  </inertial>
  <visual>
    <origin rpy="0 0 0" xyz="0.035 -0.015 -0.28"/>
    <geometry>
      <mesh filename="package://rur_detailed_description/meshes/electronics_lid.stl" scale="0.001 0.001 0.001"/>
    </geometry>
    <material name="blue"/>
  </visual>
  <collision>
    <origin rpy="0 0 0" xyz="0.035 -0.015 -0.28"/>
    <geometry>
      <mesh filename="package://rur_detailed_description/meshes/electronics_lid.stl" scale="0.001 0.001 0.001"/>
    </geometry>
  </collision>
</link>

<link name="long_bar">
  <inertial>
    <origin rpy="0 0 0" xyz="0.03584192761999582 0.003225175684225926 0.4595434632519135"/>
    <mass value="7.553317644619513"/>
    <inertia ixx="1.13396" ixy="-0.000125" ixz="-0.002615" iyy="1.139907" iyz="-0.018664" izz="0.009557"/>
  </inertial>
  <visual>
    <origin rpy="0 0 0" xyz="-0.015 -0.0 -0.291"/>
    <geometry>
      <mesh filename="package://rur_detailed_description/meshes/long_bar.stl" scale="0.001 0.001 0.001"/>
    </geometry>
    <material name="grey"/>
  </visual>
  <collision>
    <origin rpy="0 0 0" xyz="-0.015 -0.0 -0.291"/>
    <geometry>
      <mesh filename="package://rur_detailed_description/meshes/long_bar.stl" scale="0.001 0.001 0.001"/>
    </geometry>
  </collision>
</link>

<link name="head">
  <inertial>
    <origin rpy="0 0 0" xyz="-0.07213061988974884 -0.0012048920814073697 0.13382726687589575"/>
    <mass value="23.76468895609019"/>
    <inertia ixx="0.240639" ixy="-0.001586" ixz="-0.018983" iyy="0.24109" iyz="-0.000966" izz="0.174627"/>
  </inertial>
  <visual>
    <origin rpy="0 0 0" xyz="-0.111 -0.0 -1.005"/>
    <geometry>
      <mesh filename="package://rur_detailed_description/meshes/head.stl" scale="0.001 0.001 0.001"/>
    </geometry>
    <material name="white"/>
  </visual>
  <collision>
    <origin rpy="0 0 0" xyz="-0.111 -0.0 -1.005"/>
    <geometry>
      <mesh filename="package://rur_detailed_description/meshes/head.stl" scale="0.001 0.001 0.001"/>
    </geometry>
  </collision>
</link>

<link name="visor">
  <inertial>
    <origin rpy="0 0 0" xyz="0.02896510148077766 0.0680499999999997 0.031790396670437815"/>
    <mass value="1.3383367623018805"/>
    <inertia ixx="0.007337" ixy="-0.0" ixz="0.000383" iyy="0.002215" iyz="0.0" izz="0.005868"/>
  </inertial>
  <visual>
    <origin rpy="0 0 0" xyz="-0.1393 0.068 -1.129264"/>
    <geometry>
      <mesh filename="package://rur_detailed_description/meshes/visor.stl" scale="0.001 0.001 0.001"/>
    </geometry>
    <material name="blue"/>
  </visual>
  <collision>
    <origin rpy="0 0 0" xyz="-0.1393 0.068 -1.129264"/>
    <geometry>
      <mesh filename="package://rur_detailed_description/meshes/visor.stl" scale="0.001 0.001 0.001"/>
    </geometry>
  </collision>
</link>

<link name="monitor_cover">
  <inertial>
    <origin rpy="0 0 0" xyz="0.025963694079177757 0.06804999764452557 -0.03724939393816329"/>
    <mass value="1.1102091778876433"/>
    <inertia ixx="0.005505" ixy="0.0" ixz="0.000808" iyy="0.002557" iyz="-0.0" izz="0.003622"/>
  </inertial>
  <visual>
    <origin rpy="0 0 0" xyz="-0.172658 0.068 -1.211058"/>
    <geometry>
      <mesh filename="package://rur_detailed_description/meshes/monitor_cover.stl" scale="0.001 0.001 0.001"/>
    </geometry>
    <material name="white"/>
  </visual>
  <collision>
    <origin rpy="0 0 0" xyz="-0.172658 0.068 -1.211058"/>
    <geometry>
      <mesh filename="package://rur_detailed_description/meshes/monitor_cover.stl" scale="0.001 0.001 0.001"/>
    </geometry>
  </collision>
</link>

<link name="right_ear">
  <inertial>
    <origin rpy="0 0 0" xyz="0.04558838834048603 -0.006250460774062022 2.75422459194985e-06"/>
    <mass value="0.05021038391016931"/>
    <inertia ixx="3.7e-05" ixy="-2e-06" ixz="0.0" iyy="7.5e-05" iyz="-0.0" izz="3.9e-05"/>
  </inertial>
  <visual>
    <origin rpy="0 0 0" xyz="0.02025 0.134173 -1.18"/>
    <geometry>
      <mesh filename="package://rur_detailed_description/meshes/right_ear.stl" scale="0.001 0.001 0.001"/>
    </geometry>
    <material name="blue"/>
  </visual>
  <collision>
    <origin rpy="0 0 0" xyz="0.02025 0.134173 -1.18"/>
    <geometry>
      <mesh filename="package://rur_detailed_description/meshes/right_ear.stl" scale="0.001 0.001 0.001"/>
    </geometry>
  </collision>
</link>

<link name="left_ear">
  <inertial>
    <origin rpy="0 0 0" xyz="0.04558838821639881 0.006350460758356213 2.7542230829347147e-06"/>
    <mass value="0.050210384315252085"/>
    <inertia ixx="3.7e-05" ixy="2e-06" ixz="0.0" iyy="7.5e-05" iyz="0.0" izz="3.9e-05"/>
  </inertial>
  <visual>
    <origin rpy="0 0 0" xyz="0.02025 -0.134173 -1.18"/>
    <geometry>
      <mesh filename="package://rur_detailed_description/meshes/left_ear.stl" scale="0.001 0.001 0.001"/>
    </geometry>
    <material name="blue"/>
  </visual>
  <collision>
    <origin rpy="0 0 0" xyz="0.02025 -0.134173 -1.18"/>
    <geometry>
      <mesh filename="package://rur_detailed_description/meshes/left_ear.stl" scale="0.001 0.001 0.001"/>
    </geometry>
  </collision>
</link>

<link name="monitor">
  <inertial>
    <origin rpy="0 0 0" xyz="0.010564793341225787 5.000000000079698e-05 -0.037888190449721026"/>
    <mass value="0.09619500000000142"/>
    <inertia ixx="0.000157" ixy="-0.0" ixz="1.4e-05" iyy="4.6e-05" iyz="0.0" izz="0.000123"/>
  </inertial>
  <visual>
    <origin rpy="0 0 0" xyz="-0.184031 -0.0 -1.231753"/>
    <geometry>
      <mesh filename="package://rur_detailed_description/meshes/monitor.stl" scale="0.001 0.001 0.001"/>
    </geometry>
    <material name="black"/>
  </visual>
  <collision>
    <origin rpy="0 0 0" xyz="-0.184031 -0.0 -1.231753"/>
    <geometry>
      <mesh filename="package://rur_detailed_description/meshes/monitor.stl" scale="0.001 0.001 0.001"/>
    </geometry>
  </collision>
</link>

<link name="left_antenna">
  <inertial>
    <origin rpy="0 0 0" xyz="-0.06681873348160798 0.027729801813354465 -0.006847664607670945"/>
    <mass value="0.185506067385235"/>
    <inertia ixx="0.000219" ixy="-5.3e-05" ixz="-0.000119" iyy="0.001161" iyz="-3e-06" izz="0.001025"/>
  </inertial>
  <visual>
    <origin rpy="0 0 0" xyz="-0.18275 -0.076 -1.335"/>
    <geometry>
      <mesh filename="package://rur_detailed_description/meshes/left_antenna.stl" scale="0.001 0.001 0.001"/>
    </geometry>
    <material name="blue"/>
  </visual>
  <collision>
    <origin rpy="0 0 0" xyz="-0.18275 -0.076 -1.335"/>
    <geometry>
      <mesh filename="package://rur_detailed_description/meshes/left_antenna.stl" scale="0.001 0.001 0.001"/>
    </geometry>
  </collision>
</link>

<link name="right_antenna">
  <inertial>
    <origin rpy="0 0 0" xyz="-0.06681872625021491 -0.027629817768358322 -0.006847111322377364"/>
    <mass value="0.18550683738354107"/>
    <inertia ixx="0.000219" ixy="5.3e-05" ixz="-0.000119" iyy="0.001161" iyz="3e-06" izz="0.001025"/>
  </inertial>
  <visual>
    <origin rpy="0 0 0" xyz="-0.18275 0.076 -1.335"/>
    <geometry>
      <mesh filename="package://rur_detailed_description/meshes/right_antenna.stl" scale="0.001 0.001 0.001"/>
    </geometry>
    <material name="blue"/>
  </visual>
  <collision>
    <origin rpy="0 0 0" xyz="-0.18275 0.076 -1.335"/>
    <geometry>
      <mesh filename="package://rur_detailed_description/meshes/right_antenna.stl" scale="0.001 0.001 0.001"/>
    </geometry>
  </collision>
</link>

<link name="camera_link">
  <inertial>
    <origin rpy="0 0 0" xyz="-0.001604468363459316 0.07205272744017827 -0.002548711859325259"/>
    <mass value="0.3739643327489875"/>
    <inertia ixx="0.001081" ixy="0.0" ixz="1e-06" iyy="0.000322" iyz="0.0" izz="0.001051"/>
  </inertial>
  <visual>
    <origin rpy="0 0 0" xyz="-0.18275 0.072 -1.335"/>
    <geometry>
      <mesh filename="package://rur_detailed_description/meshes/camera_link.stl" scale="0.001 0.001 0.001"/>
    </geometry>
    <material name="white"/>
  </visual>
  <collision>
    <origin rpy="0 0 0" xyz="-0.18275 0.072 -1.335"/>
    <geometry>
      <mesh filename="package://rur_detailed_description/meshes/camera_link.stl" scale="0.001 0.001 0.001"/>
    </geometry>
  </collision>
</link>

<link name="realsense">
  <inertial>
    <origin rpy="0 0 0" xyz="0.004830412362641728 5.000000000015024e-05 0.00650000017136354"/>
    <mass value="0.03735280587989202"/>
    <inertia ixx="2.3e-05" ixy="0.0" ixz="0.0" iyy="3e-06" iyz="0.0" izz="2.2e-05"/>
  </inertial>
  <visual>
    <origin rpy="0 0 0" xyz="-0.213442 -0.0 -1.3275"/>
    <geometry>
      <mesh filename="package://rur_detailed_description/meshes/realsense.stl" scale="0.001 0.001 0.001"/>
    </geometry>
    <material name="grey"/>
  </visual>
  <collision>
    <origin rpy="0 0 0" xyz="-0.213442 -0.0 -1.3275"/>
    <geometry>
      <mesh filename="package://rur_detailed_description/meshes/realsense.stl" scale="0.001 0.001 0.001"/>
    </geometry>
  </collision>
</link>

<joint name="motor_right" type="continuous">
  <origin rpy="0 0 0" xyz="0.0 -0.227 0.099839"/>
  <parent link="base_link"/>
  <child link="right_wheel"/>
  <axis xyz="0.0 1.0 0.0"/>
</joint>

<joint name="motor_left" type="continuous">
  <origin rpy="0 0 0" xyz="0.0 0.227 0.099839"/>
  <parent link="base_link"/>
  <child link="left_wheel"/>
  <axis xyz="0.0 1.0 0.0"/>
</joint>

<joint name="Rigid3" type="fixed">
  <origin rpy="0 0 0" xyz="0.0 0.027 0.000161"/>
  <parent link="right_wheel"/>
  <child link="right_tyre"/>
</joint>

<joint name="Rigid4" type="fixed">
  <origin rpy="0 0 0" xyz="0.0 -0.027 0.000161"/>
  <parent link="left_wheel"/>
  <child link="left_tyre"/>
</joint>

<joint name="Rigid5" type="fixed">
  <origin rpy="0 0 0" xyz="0.172 0.0 0.07"/>
  <parent link="base_link"/>
  <child link="front_caster"/>
</joint>

<joint name="Rigid6" type="fixed">
  <origin rpy="0 0 0" xyz="-0.172 0.0 0.07"/>
  <parent link="base_link"/>
  <child link="back_caster"/>
</joint>

<joint name="Rigid7" type="fixed">
  <origin rpy="0 0 0" xyz="0.225 0.0002 0.25"/>
  <parent link="base_link"/>
  <child link="lid"/>
</joint>

<joint name="Rigid8" type="fixed">
  <origin rpy="0 0 0" xyz="-0.0675 -0.0002 0.05"/>
  <parent link="lid"/>
  <child link="lidar"/>
</joint>

<joint name="Rigid9" type="fixed">
  <origin rpy="0 0 0" xyz="-0.26 0.0148 0.03"/>
  <parent link="lid"/>
  <child link="electronics_lid"/>
</joint>

<joint name="Rigid10" type="fixed">
  <origin rpy="0 0 0" xyz="-0.21 -0.0002 0.041"/>
  <parent link="lid"/>
  <child link="long_bar"/>
</joint>

<!--
<joint name="slider" type="prismatic">
  <origin rpy="0 0 0" xyz="0.096 0.0 0.714"/>
  <parent link="long_bar"/>
  <child link="head"/>
  <axis xyz="-0.0 0.0 1.0"/>
  <limit effort="100" lower="-0.6" upper="0.0" velocity="100"/>
</joint>
-->

<joint name="slider" type="fixed">
  <origin rpy="0 0 0" xyz="0.096 0.0 0.714"/>
  <parent link="long_bar"/>
  <child link="head"/>
</joint>

<joint name="Rigid12" type="fixed">
  <origin rpy="0 0 0" xyz="0.0283 -0.068 0.124264"/>
  <parent link="head"/>
  <child link="visor"/>
</joint>

<joint name="Rigid13" type="fixed">
  <origin rpy="0 0 0" xyz="0.033358 0.0 0.081794"/>
  <parent link="visor"/>
  <child link="monitor_cover"/>
</joint>

<joint name="Rigid14" type="fixed">
  <origin rpy="0 0 0" xyz="-0.13125 -0.134173 0.175"/>
  <parent link="head"/>
  <child link="right_ear"/>
</joint>

<joint name="Rigid15" type="fixed">
  <origin rpy="0 0 0" xyz="-0.13125 0.134173 0.175"/>
  <parent link="head"/>
  <child link="left_ear"/>
</joint>

<joint name="Rigid16" type="fixed">
  <origin rpy="0 0 0" xyz="0.011373 0.068 0.020695"/>
  <parent link="monitor_cover"/>
  <child link="monitor"/>
</joint>

<joint name="Rigid17" type="fixed">
  <origin rpy="0 0 0" xyz="0.07175 0.076 0.33"/>
  <parent link="head"/>
  <child link="left_antenna"/>
</joint>

<joint name="Rigid18" type="fixed">
  <origin rpy="0 0 0" xyz="0.07175 -0.076 0.33"/>
  <parent link="head"/>
  <child link="right_antenna"/>
</joint>

<!-- <joint name="camera_joint" type="revolute">
  <origin rpy="0 0 0" xyz="0.07175 -0.072 0.33"/>
  <parent link="head"/>
  <child link="camera_link"/>
  <axis xyz="0.0 1.0 -0.0"/>
  <limit effort="100" lower="-3.141593" upper="3.141593" velocity="100"/>
</joint> -->

<joint name="camera_joint" type="fixed">
  <origin rpy="0 0 0" xyz="0.07175 -0.072 0.33"/>
  <parent link="head"/>
  <child link="camera_link"/>
</joint>

<joint name="Rigid20" type="fixed">
  <origin rpy="0 0 0" xyz="0.030692 0.072 -0.0075"/>
  <parent link="camera_link"/>
  <child link="realsense"/>
</joint>

</robot>
